<?xml version="1.0" encoding="utf-8"?>
<!-- =================================================================================== -->
<!-- |    This document was autogenerated by xacro from smart_define.xacro             | -->
<!-- |    EDITING THIS FILE BY HAND IS NOT RECOMMENDED                                 | -->
<!-- =================================================================================== -->
<robot name="smart_define">
  <!-- <xacro:include filename="/opt/ros/melodic/share/turtlebot3_description/urdf/common_properties.xacro"/>
  <xacro:include filename="/opt/ros/melodic/share/turtlebot3_description/urdf/smart.gazebo.xacro"/> -->
  <link name="base_footprint"/>
  <!--Car Body-->
  <link name="base_link">
    <collision>
      <origin rpy="0 0 0" xyz="0 0 -0.3"/>
      <geometry>
        <box size="1.5 0.68 0.6"/>
      </geometry>
    </collision>
    <visual>
      <origin rpy="0 0 0" xyz="0 0 -0.3"/>
      <geometry>
        <box size="1.5 0.68 0.6"/>
      </geometry>
      <material name="Cyan">
        <color rgba="0 0.0 1.0 1.0"/>
      </material>
    </visual>
  </link>
  <joint name="base_footprint_base_link" type="fixed">
    <parent link="base_footprint"/>
    <child link="base_link"/>
    <origin rpy="0 0 0" xyz="0 0 0.9"/>
  </joint>
  <!-- front left wheel steering -->
  <joint name="front_left_steering_joint" type="revolute">
    <parent link="base_link"/>
    <child link="front_left_steering_link"/>
    <origin rpy="0 0 0" xyz="0.5 0.3 -0.6"/>
    <axis xyz="0 0 1"/>
    <limit effort="1000000.0" lower="-0.6" upper="0.6" velocity="10000.0"/>
    <dynamics damping="10.0" friction="0.0"/>
  </joint>
  <link name="front_left_steering_link">
    <visual>
      <origin rpy="1.57079634179 0 0" xyz="0 0 0"/>
      <geometry>
        <cylinder length="0.01" radius="0.1"/>
      </geometry>
      <material name="Cyan">
        <color rgba="0 1.0 0.0 1.0"/>
      </material>
    </visual>
    <inertial>
      <origin rpy="0 0 0" xyz="0 0 0"/>
      <mass value="5"/>
      <inertia ixx="0.012" ixy="0.000000" ixz="0.000000" iyy="0.025" iyz="0.000000" izz="0.012"/>
    </inertial>
  </link>
  <!-- front left wheel -->
  <joint name="front_left_wheel_joint" type="continuous">
    <parent link="front_left_steering_link"/>
    <child link="front_left_wheel_link"/>
    <origin rpy="0 0 0" xyz="0 0 0"/>
    <axis xyz="0 1 0"/>
    <dynamics damping="0.1"/>
    <limit effort="1000000" velocity="10000"/>
    <joint_properties damping="0.0" friction="0.0"/>
  </joint>
  <link name="front_left_wheel_link">
    <collision>
      <origin rpy="1.57079634179 0 0" xyz="0 0 0"/>
      <geometry>
        <cylinder length="0.165" radius="0.3"/>
      </geometry>
    </collision>
    <visual>
      <origin rpy="1.57079634179 0 0 " xyz="0 0 0"/>
      <geometry>
        <cylinder length="0.165" radius="0.3"/>
      </geometry>
    </visual>
    <inertial>
      <origin rpy="0 0 0" xyz="0 0 0"/>
      <mass value="20"/>
      <inertia ixx="0.5" ixy="0.000000" ixz="0.000000" iyy="0.9" iyz="0.000000" izz="0.5"/>
    </inertial>
  </link>
  <!-- front right wheel steering -->
  <joint name="front_right_steering_joint" type="revolute">
    <parent link="base_link"/>
    <child link="front_right_steering_link"/>
    <origin rpy="0 0 0" xyz="0.5 -0.3 -0.6"/>
    <axis xyz="0 0 1"/>
    <limit effort="1000000.0" lower="-0.6" upper="0.6" velocity="10000.0"/>
    <dynamics damping="10.0" friction="0.0"/>
  </joint>
  <link name="front_right_steering_link">
    <visual>
      <origin rpy="1.57079634179 0 0" xyz="0 0 0"/>
      <geometry>
        <cylinder length="0.01" radius="0.1"/>
      </geometry>
      <material name="Cyan">
        <color rgba="0 1.0 0.0 1.0"/>
      </material>
    </visual>
    <inertial>
      <origin rpy="0 0 0" xyz="0 0 0"/>
      <mass value="5"/>
      <inertia ixx="0.012" ixy="0.000000" ixz="0.000000" iyy="0.025" iyz="0.000000" izz="0.012"/>
    </inertial>
  </link>
  <!-- front right wheel -->
  <joint name="front_right_wheel_joint" type="continuous">
    <parent link="front_right_steering_link"/>
    <child link="front_right_wheel_link"/>
    <origin rpy="0 0 0" xyz="0 0 0"/>
    <axis xyz="0 1 0"/>
    <dynamics damping="0.1"/>
    <limit effort="1000000" velocity="10000"/>
    <joint_properties damping="0.0" friction="0.0"/>
  </joint>
  <link name="front_right_wheel_link">
    <collision>
      <origin rpy="1.57079634179 0 0" xyz="0 0 0"/>
      <geometry>
        <cylinder length="0.165" radius="0.3"/>
      </geometry>
    </collision>
    <visual>
      <origin rpy="1.57079634179 0 0 " xyz="0 0 0"/>
      <geometry>
        <cylinder length="0.165" radius="0.3"/>
      </geometry>
    </visual>
    <inertial>
      <origin rpy="0 0 0" xyz="0 0 0"/>
      <mass value="20"/>
      <inertia ixx="0.5" ixy="0.000000" ixz="0.000000" iyy="0.9" iyz="0.000000" izz="0.5"/>
    </inertial>
  </link>
  <!-- rear left wheel steering -->
  <joint name="rear_left_steering_joint" type="revolute">
    <parent link="base_link"/>
    <child link="rear_left_steering_link"/>
    <origin rpy="0 0 0" xyz="-0.5 0.3 -0.6"/>
    <axis xyz="0 0 1"/>
    <limit effort="1000000.0" lower="-0.6" upper="0.6" velocity="10000.0"/>
    <dynamics damping="10.0" friction="0.0"/>
  </joint>
  <link name="rear_left_steering_link">
    <visual>
      <origin rpy="1.57079634179 0 0" xyz="0 0 0"/>
      <geometry>
        <cylinder length="0.01" radius="0.1"/>
      </geometry>
      <material name="Cyan">
        <color rgba="0 1.0 0.0 1.0"/>
      </material>
    </visual>
    <inertial>
      <origin rpy="0 0 0" xyz="0 0 0"/>
      <mass value="5"/>
      <inertia ixx="0.012" ixy="0.000000" ixz="0.000000" iyy="0.025" iyz="0.000000" izz="0.012"/>
    </inertial>
  </link>
  <!-- rear left wheel -->
  <joint name="rear_left_wheel_joint" type="continuous">
    <parent link="rear_left_steering_link"/>
    <child link="rear_left_wheel_link"/>
    <origin rpy="0 0 0" xyz="0 0 0"/>
    <axis xyz="0 1 0"/>
    <dynamics damping="0.1"/>
    <limit effort="1000000" velocity="10000"/>
    <joint_properties damping="0.0" friction="0.0"/>
  </joint>
  <link name="rear_left_wheel_link">
    <collision>
      <origin rpy="1.57079634179 0 0" xyz="0 0 0"/>
      <geometry>
        <cylinder length="0.165" radius="0.3"/>
      </geometry>
    </collision>
    <visual>
      <origin rpy="1.57079634179 0 0 " xyz="0 0 0"/>
      <geometry>
        <cylinder length="0.165" radius="0.3"/>
      </geometry>
    </visual>
    <inertial>
      <origin rpy="0 0 0" xyz="0 0 0"/>
      <mass value="20"/>
      <inertia ixx="0.5" ixy="0.000000" ixz="0.000000" iyy="0.9" iyz="0.000000" izz="0.5"/>
    </inertial>
  </link>
  <!-- rear right wheel steering -->
  <joint name="rear_right_steering_joint" type="revolute">
    <parent link="base_link"/>
    <child link="rear_right_steering_link"/>
    <origin rpy="0 0 0" xyz="-0.5 -0.3 -0.6"/>
    <axis xyz="0 0 1"/>
    <limit effort="1000000.0" lower="-0.6" upper="0.6" velocity="10000.0"/>
    <dynamics damping="10.0" friction="0.0"/>
  </joint>
  <link name="rear_right_steering_link">
    <visual>
      <origin rpy="1.57079634179 0 0" xyz="0 0 0"/>
      <geometry>
        <cylinder length="0.01" radius="0.1"/>
      </geometry>
      <material name="Cyan">
        <color rgba="0 1.0 0.0 1.0"/>
      </material>
    </visual>
    <inertial>
      <origin rpy="0 0 0" xyz="0 0 0"/>
      <mass value="5"/>
      <inertia ixx="0.012" ixy="0.000000" ixz="0.000000" iyy="0.025" iyz="0.000000" izz="0.012"/>
    </inertial>
  </link>
  <!-- rear right wheel -->
  <joint name="rear_right_wheel_joint" type="continuous">
    <parent link="rear_right_steering_link"/>
    <child link="rear_right_wheel_link"/>
    <origin rpy="0 0 0" xyz="0 0 0"/>
    <axis xyz="0 1 0"/>
    <dynamics damping="0.1"/>
    <limit effort="1000000" velocity="10000"/>
    <joint_properties damping="0.0" friction="0.0"/>
  </joint>
  <link name="rear_right_wheel_link">
    <collision>
      <origin rpy="1.57079634179 0 0" xyz="0 0 0"/>
      <geometry>
        <cylinder length="0.165" radius="0.3"/>
      </geometry>
    </collision>
    <visual>
      <origin rpy="1.57079634179 0 0 " xyz="0 0 0"/>
      <geometry>
        <cylinder length="0.165" radius="0.3"/>
      </geometry>
    </visual>
    <inertial>
      <origin rpy="0 0 0" xyz="0 0 0"/>
      <mass value="20"/>
      <inertia ixx="0.5" ixy="0.000000" ixz="0.000000" iyy="0.9" iyz="0.000000" izz="0.5"/>
    </inertial>
  </link>
  <!-- laser  -->
  <joint name="scan_joint" type="fixed">
    <parent link="base_link"/>
    <child link="base_scan"/>
    <origin rpy="0 0 0" xyz="0.0 0.0 0.05"/>
  </joint>
  <link name="base_scan">
    <visual>
      <origin rpy="0 0 0" xyz="0 0 0"/>
      <geometry>
        <mesh filename="package://turtlebot3_description/meshes/sensors/lds.stl" scale="0.001 0.001 0.001"/>
      </geometry>
      <material name="dark"/>
    </visual>
    <collision>
      <origin rpy="0 0 0" xyz="0.015 0 -0.0065"/>
      <geometry>
        <cylinder length="0.0315" radius="0.055"/>
      </geometry>
    </collision>
    <inertial>
      <mass value="0.114"/>
      <origin xyz="0 0 0"/>
      <inertia ixx="0.001" ixy="0.0" ixz="0.0" iyy="0.001" iyz="0.0" izz="0.001"/>
    </inertial>
  </link>
  <!--camera  -->
  <joint name="camera_joint" type="fixed">
    <origin rpy="0 0 0" xyz="0.7 -0.07 0.02"/>
    <parent link="base_link"/>
    <child link="camera_link"/>
  </joint>
  <link name="camera_link">
    <visual>
      <origin rpy="1.57 0 1.57" xyz="0 0 0"/>
      <geometry>
        <mesh filename="package://turtlebot3_description/meshes/sensors/r200.dae"/>
      </geometry>
    </visual>
    <collision>
      <origin rpy="0 0 0" xyz="0.003 0.065 0.007"/>
      <geometry>
        <box size="0.012 0.132 0.020"/>
      </geometry>
    </collision>
  </link>
</robot>

