<?xml version="1.0" ?>
<robot name="smart_define" xmlns:xacro="http://ros.org/wiki/xacro">
 <xacro:property name="PI" value="3.1415926835897931"/>
 <xacro:include filename="$(find turtlebot3_description)/urdf/common_properties.xacro"/>
 <xacro:include filename="$(find turtlebot3_description)/urdf/smart.gazebo.xacro"/>

  <!-- base -->
  <xacro:property name="base_length" value="1.5"/>
  <xacro:property name="base_width" value="0.68"/>
  <xacro:property name="base_height" value="0.6"/>
  <xacro:property name="base_collision_height" value="-0.3"/>
  <xacro:property name="base_mass" value="956"/>
  <xacro:property name="base_mass_ixx" value="343"/>
  <xacro:property name="base_mass_iyy" value="728"/>
  <xacro:property name="base_mass_izz" value="772"/>

  <!-- rear tyre -->
  <xacro:property name="rear_tyre_x" value="-0.5"/>
  <xacro:property name="rear_tyre_y" value="0.642"/>
  <xacro:property name="rear_tyre_r" value="0.3"/>
  <xacro:property name="rear_tyre_length" value="0.165"/>
  <xacro:property name="rear_tyre_mass" value="20"/>
  <xacro:property name="rear_tyre_mass_ixx" value="0.5"/>
  <xacro:property name="rear_tyre_mass_iyy" value="0.9"/>
  <xacro:property name="rear_tyre_mass_izz" value="0.5"/> 

  <!-- front tyre -->
  <xacro:property name="front_tyre_x" value="0.5"/>
  <xacro:property name="front_tyre_y" value="0.3"/>
  <xacro:property name="front_tyre_r" value="0.3"/>
  
  <xacro:property name="front_tyre_right_y" value="-0.3"/>
  <xacro:property name="front_tyre_z" value="-0.6"/>
  <xacro:property name="front_tyre_length" value="0.165"/>
  <xacro:property name="front_tyre_mass" value="20"/>
  <xacro:property name="front_tyre_mass_ixx" value="0.5"/>
  <xacro:property name="front_tyre_mass_iyy" value="0.9"/>
  <xacro:property name="front_tyre_mass_izz" value="0.5"/>  

  <!-- steering -->
  <xacro:property name="str_angle" value="0.6"/>    
  <xacro:property name="str_length" value="0.01"/>
  <xacro:property name="str_radius" value="0.1"/>
  <xacro:property name="str_mass" value="5"/>
  <xacro:property name="str_mass_ixx" value="0.012"/>
  <xacro:property name="str_mass_iyy" value="0.025"/>
  <xacro:property name="str_mass_izz" value="0.012"/> 


  <link name="base_footprint"/>
  <!--Car Body-->
  <link name="base_link">
    <collision>
      <origin xyz="0 0 ${base_collision_height}" rpy="0 0 0"/>  
      <geometry>
        <box size="${base_length} ${base_width} ${base_height}"/>
      </geometry>
    </collision>

    <visual>
      <origin xyz="0 0 ${base_collision_height}" rpy="0 0 0"/>  
      <geometry>
        <box size="${base_length} ${base_width} ${base_height}"/>
      </geometry>
      <material name="Cyan">
        <color rgba="0 0.0 1.0 1.0"/>
      </material>
    </visual>
  </link>
  <joint name="base_footprint_base_link" type="fixed">
    <parent link="base_footprint"/>
    <child link="base_link"/>
    <origin xyz="0 0 0.9" rpy="0 0 0"/>
  </joint>  

  <!-- front left wheel steering -->
  <joint name="front_left_steering_joint" type="revolute">
    <parent link="base_link"/>
    <child link="front_left_steering_link"/>
    <origin xyz="${front_tyre_x} ${front_tyre_y} ${front_tyre_z}" rpy="0 0 0"/>
    <axis xyz="0 0 1"/>
    <limit lower="${-str_angle}" upper="${str_angle}" effort="1000000.0" velocity="10000.0"/>
    <dynamics damping="10.0" friction="0.0"/>
  </joint>

  <link name="front_left_steering_link">
    <visual>
      <origin xyz="0 0 0" rpy="${PI/2} 0 0"/>
      <geometry>
        <cylinder length="${str_length}" radius="${str_radius}"/>
      </geometry>
            <material name="Cyan">
        <color rgba="0 1.0 0.0 1.0"/>
      </material>
    </visual>
    <inertial>
      <origin xyz="0 0 0" rpy="0 0 0"/>
      <mass value="${str_mass}"/>
      <inertia
      ixx="${str_mass_ixx}"  ixy="0.000000"  ixz="0.000000"
      iyy="${str_mass_iyy}"  iyz="0.000000"
      izz="${str_mass_izz}"/>
    </inertial>
  </link>
<!-- front left wheel -->
  <joint name="front_left_wheel_joint" type="continuous">
    <parent link="front_left_steering_link"/>
    <child link="front_left_wheel_link"/>
    <origin xyz="0 0 0" rpy="0 0 0"/>
    <axis xyz="0 1 0"/>
    <dynamics damping="0.1"/>
    <limit effort="1000000" velocity="10000" />
    <joint_properties damping="0.0" friction="0.0" />
  </joint>

  <link name="front_left_wheel_link">
    <collision>
      <origin xyz="0 0 0" rpy="${PI/2} 0 0"/>
      <geometry>
        <cylinder length="${front_tyre_length}" radius="${front_tyre_r}"/>
      </geometry>
    </collision>
    <visual>
      <origin xyz="0 0 0" rpy="${PI/2} 0 0 "/>
      <geometry>
        <cylinder length="${front_tyre_length}" radius="${front_tyre_r}"/>
      </geometry>  
    </visual>
    <inertial>
      <origin xyz="0 0 0" rpy="0 0 0"/>
      <mass value="${front_tyre_mass}"/>
      <inertia
        ixx="${front_tyre_mass_ixx}"  ixy="0.000000"  ixz="0.000000"
        iyy="${front_tyre_mass_iyy}"  iyz="0.000000"
        izz="${front_tyre_mass_izz}"/>
    </inertial>
  </link>  

  <!-- front right wheel steering -->
  <joint name="front_right_steering_joint" type="revolute">
    <parent link="base_link"/>
    <child link="front_right_steering_link"/>
    <origin xyz="${front_tyre_x} ${front_tyre_right_y} ${front_tyre_z}" rpy="0 0 0"/>
    <axis xyz="0 0 1"/>
    <limit lower="${-str_angle}" upper="${str_angle}" effort="1000000.0" velocity="10000.0"/>
    <dynamics damping="10.0" friction="0.0"/>
  </joint>

  <link name="front_right_steering_link">
    <visual>
      <origin xyz="0 0 0" rpy="${PI/2} 0 0"/>
      <geometry>
        <cylinder length="${str_length}" radius="${str_radius}"/>
      </geometry>
            <material name="Cyan">
        <color rgba="0 1.0 0.0 1.0"/>
      </material>
    </visual>
    <inertial>
      <origin xyz="0 0 0" rpy="0 0 0"/>
      <mass value="${str_mass}"/>
      <inertia
      ixx="${str_mass_ixx}"  ixy="0.000000"  ixz="0.000000"
      iyy="${str_mass_iyy}"  iyz="0.000000"
      izz="${str_mass_izz}"/>
    </inertial>
  </link>
<!-- front right wheel -->
  <joint name="front_right_wheel_joint" type="continuous">
    <parent link="front_right_steering_link"/>
    <child link="front_right_wheel_link"/>
    <origin xyz="0 0 0" rpy="0 0 0"/>
    <axis xyz="0 1 0"/>
    <dynamics damping="0.1"/>
    <limit effort="1000000" velocity="10000" />
    <joint_properties damping="0.0" friction="0.0" />
  </joint>

  <link name="front_right_wheel_link">
    <collision>
      <origin xyz="0 0 0" rpy="${PI/2} 0 0"/>
      <geometry>
        <cylinder length="${front_tyre_length}" radius="${front_tyre_r}"/>
      </geometry>
    </collision>
    <visual>
      <origin xyz="0 0 0" rpy="${PI/2} 0 0 "/>
      <geometry>
        <cylinder length="${front_tyre_length}" radius="${front_tyre_r}"/>
      </geometry>  
    </visual>
    <inertial>
      <origin xyz="0 0 0" rpy="0 0 0"/>
      <mass value="${front_tyre_mass}"/>
      <inertia
        ixx="${front_tyre_mass_ixx}"  ixy="0.000000"  ixz="0.000000"
        iyy="${front_tyre_mass_iyy}"  iyz="0.000000"
        izz="${front_tyre_mass_izz}"/>
    </inertial>
  </link>  

    <!-- rear left wheel steering -->
  <joint name="rear_left_steering_joint" type="revolute">
    <parent link="base_link"/>
    <child link="rear_left_steering_link"/>
    <origin xyz="${rear_tyre_x} ${front_tyre_y} ${front_tyre_z}" rpy="0 0 0"/>
    <axis xyz="0 0 1"/>
    <limit lower="${-str_angle}" upper="${str_angle}" effort="1000000.0" velocity="10000.0"/>
    <dynamics damping="10.0" friction="0.0"/>
  </joint>

  <link name="rear_left_steering_link">
    <visual>
      <origin xyz="0 0 0" rpy="${PI/2} 0 0"/>
      <geometry>
        <cylinder length="${str_length}" radius="${str_radius}"/>
      </geometry>
            <material name="Cyan">
        <color rgba="0 1.0 0.0 1.0"/>
      </material>
    </visual>
    <inertial>
      <origin xyz="0 0 0" rpy="0 0 0"/>
      <mass value="${str_mass}"/>
      <inertia
      ixx="${str_mass_ixx}"  ixy="0.000000"  ixz="0.000000"
      iyy="${str_mass_iyy}"  iyz="0.000000"
      izz="${str_mass_izz}"/>
    </inertial>
  </link>
   <!-- rear left wheel -->
  <joint name="rear_left_wheel_joint" type="continuous">
    <parent link="rear_left_steering_link"/>
    <child link="rear_left_wheel_link"/>
    <origin xyz="0 0 0" rpy="0 0 0"/>
    <axis xyz="0 1 0"/>
    <dynamics damping="0.1"/>
    <limit effort="1000000" velocity="10000" />
    <joint_properties damping="0.0" friction="0.0" />
  </joint>

  <link name="rear_left_wheel_link">
    <collision>
      <origin xyz="0 0 0" rpy="${PI/2} 0 0"/>
      <geometry>
        <cylinder length="${front_tyre_length}" radius="${front_tyre_r}"/>
      </geometry>
    </collision>
    <visual>
      <origin xyz="0 0 0" rpy="${PI/2} 0 0 "/>
      <geometry>
        <cylinder length="${front_tyre_length}" radius="${front_tyre_r}"/>
      </geometry>  
    </visual>
    <inertial>
      <origin xyz="0 0 0" rpy="0 0 0"/>
      <mass value="${front_tyre_mass}"/>
      <inertia
        ixx="${front_tyre_mass_ixx}"  ixy="0.000000"  ixz="0.000000"
        iyy="${front_tyre_mass_iyy}"  iyz="0.000000"
        izz="${front_tyre_mass_izz}"/>
    </inertial>
  </link>  
   

    <!-- rear right wheel steering -->
  <joint name="rear_right_steering_joint" type="revolute">
    <parent link="base_link"/>
    <child link="rear_right_steering_link"/>
    <origin xyz="${rear_tyre_x} ${front_tyre_right_y} ${front_tyre_z}" rpy="0 0 0"/>
    <axis xyz="0 0 1"/>
    <limit lower="${-str_angle}" upper="${str_angle}" effort="1000000.0" velocity="10000.0"/>
    <dynamics damping="10.0" friction="0.0"/>
  </joint>

  <link name="rear_right_steering_link">
    <visual>
      <origin xyz="0 0 0" rpy="${PI/2} 0 0"/>
      <geometry>
        <cylinder length="${str_length}" radius="${str_radius}"/>
      </geometry>
            <material name="Cyan">
        <color rgba="0 1.0 0.0 1.0"/>
      </material>
    </visual>
    <inertial>
      <origin xyz="0 0 0" rpy="0 0 0"/>
      <mass value="${str_mass}"/>
      <inertia
      ixx="${str_mass_ixx}"  ixy="0.000000"  ixz="0.000000"
      iyy="${str_mass_iyy}"  iyz="0.000000"
      izz="${str_mass_izz}"/>
    </inertial>
  </link>
   <!-- rear right wheel -->
   <joint name="rear_right_wheel_joint" type="continuous">
    <parent link="rear_right_steering_link"/>
    <child link="rear_right_wheel_link"/>
    <origin xyz="0 0 0" rpy="0 0 0"/>
    <axis xyz="0 1 0"/>
    <dynamics damping="0.1"/>
    <limit effort="1000000" velocity="10000" />
    <joint_properties damping="0.0" friction="0.0" />
  </joint>

  <link name="rear_right_wheel_link">
    <collision>
      <origin xyz="0 0 0" rpy="${PI/2} 0 0"/>
      <geometry>
        <cylinder length="${front_tyre_length}" radius="${front_tyre_r}"/>
      </geometry>
    </collision>
    <visual>
      <origin xyz="0 0 0" rpy="${PI/2} 0 0 "/>
      <geometry>
        <cylinder length="${front_tyre_length}" radius="${front_tyre_r}"/>
      </geometry>  
    </visual>
    <inertial>
      <origin xyz="0 0 0" rpy="0 0 0"/>
      <mass value="${front_tyre_mass}"/>
      <inertia
        ixx="${front_tyre_mass_ixx}"  ixy="0.000000"  ixz="0.000000"
        iyy="${front_tyre_mass_iyy}"  iyz="0.000000"
        izz="${front_tyre_mass_izz}"/>
    </inertial>
  </link>  

  <!-- laser  -->
  <joint name="scan_joint" type="fixed">
    <parent link="base_link"/>
    <child link="base_scan"/>
    <origin xyz="0.0 0.0 0.05" rpy="0 0 0"/>
  </joint>

  <link name="base_scan">
    <visual>
      <origin xyz="0 0 0" rpy="0 0 0"/>
      <geometry>
        <mesh filename="package://turtlebot3_description/meshes/sensors/lds.stl" scale="0.001 0.001 0.001"/>
      </geometry>
      <material name="dark"/>
    </visual>

    <collision>
      <origin xyz="0.015 0 -0.0065" rpy="0 0 0"/>
      <geometry>
        <cylinder length="0.0315" radius="0.055"/>
      </geometry>
    </collision>

    <inertial>
      <mass value="0.114" />
      <origin xyz="0 0 0" />
      <inertia ixx="0.001" ixy="0.0" ixz="0.0"
               iyy="0.001" iyz="0.0"
               izz="0.001" />
    </inertial>
  </link>
  <!--camera  -->
  <joint name="camera_joint" type="fixed">
    <origin xyz="0.7 -0.07 0.02" rpy="0 0 0"/>
    <parent link="base_link"/>
    <child link="camera_link"/>
  </joint>

  <link name="camera_link">
    <visual>
     <origin xyz="0 0 0" rpy="1.57 0 1.57"/>
      <geometry>
       <mesh filename="package://turtlebot3_description/meshes/sensors/r200.dae" />
      </geometry>
    </visual>
    <collision>
      <origin xyz="0.003 0.065 0.007" rpy="0 0 0"/>
      <geometry>
        <box size="0.012 0.132 0.020"/>
      </geometry>
    </collision>
  </link>

</robot>